[Mon May 23 09:46:16.421252 2016] [:error] [pid 26703] [client 10.0.2.106:37426] mod_wsgi (pid=26703): Target WSGI script '/var/www/pydrive/controller.wsgi' cannot be loaded as Python module.
[Mon May 23 09:46:16.421337 2016] [:error] [pid 26703] [client 10.0.2.106:37426] mod_wsgi (pid=26703): Exception occurred processing WSGI script '/var/www/pydrive/controller.wsgi'.
[Mon May 23 09:46:16.421388 2016] [:error] [pid 26703] [client 10.0.2.106:37426] Traceback (most recent call last):
[Mon May 23 09:46:16.421424 2016] [:error] [pid 26703] [client 10.0.2.106:37426]   File "/var/www/pydrive/controller.wsgi", line 8, in <module>
[Mon May 23 09:46:16.421528 2016] [:error] [pid 26703] [client 10.0.2.106:37426]     from pythonapp import app as application
[Mon May 23 09:46:16.421619 2016] [:error] [pid 26703] [client 10.0.2.106:37426]   File "/var/www/pydrive/pythonapp/__init__.py", line 36
[Mon May 23 09:46:16.421630 2016] [:error] [pid 26703] [client 10.0.2.106:37426]     else:
[Mon May 23 09:46:16.421637 2016] [:error] [pid 26703] [client 10.0.2.106:37426]        ^
[Mon May 23 09:46:16.421644 2016] [:error] [pid 26703] [client 10.0.2.106:37426] IndentationError: expected an indented block
[Mon May 23 09:47:51.006409 2016] [:error] [pid 26699] [client 10.0.2.106:37434] mod_wsgi (pid=26699): Target WSGI script '/var/www/pydrive/controller.wsgi' cannot be loaded as Python module.
[Mon May 23 09:47:51.006620 2016] [:error] [pid 26699] [client 10.0.2.106:37434] mod_wsgi (pid=26699): Exception occurred processing WSGI script '/var/www/pydrive/controller.wsgi'.
[Mon May 23 09:47:51.006727 2016] [:error] [pid 26699] [client 10.0.2.106:37434] Traceback (most recent call last):
[Mon May 23 09:47:51.006798 2016] [:error] [pid 26699] [client 10.0.2.106:37434]   File "/var/www/pydrive/controller.wsgi", line 8, in <module>
[Mon May 23 09:47:51.006969 2016] [:error] [pid 26699] [client 10.0.2.106:37434]     from pythonapp import app as application
[Mon May 23 09:47:51.007088 2016] [:error] [pid 26699] [client 10.0.2.106:37434]   File "/var/www/pydrive/pythonapp/__init__.py", line 37
[Mon May 23 09:47:51.007122 2016] [:error] [pid 26699] [client 10.0.2.106:37434]     else:
[Mon May 23 09:47:51.007146 2016] [:error] [pid 26699] [client 10.0.2.106:37434]        ^
[Mon May 23 09:47:51.007168 2016] [:error] [pid 26699] [client 10.0.2.106:37434] SyntaxError: invalid syntax
[Mon May 23 09:48:14.581713 2016] [:error] [pid 26703] [client 10.0.2.106:37438] mod_wsgi (pid=26703): Target WSGI script '/var/www/pydrive/controller.wsgi' cannot be loaded as Python module.
[Mon May 23 09:48:14.581774 2016] [:error] [pid 26703] [client 10.0.2.106:37438] mod_wsgi (pid=26703): Exception occurred processing WSGI script '/var/www/pydrive/controller.wsgi'.
[Mon May 23 09:48:14.581809 2016] [:error] [pid 26703] [client 10.0.2.106:37438] Traceback (most recent call last):
[Mon May 23 09:48:14.581840 2016] [:error] [pid 26703] [client 10.0.2.106:37438]   File "/var/www/pydrive/controller.wsgi", line 8, in <module>
[Mon May 23 09:48:14.581886 2016] [:error] [pid 26703] [client 10.0.2.106:37438]     from pythonapp import app as application
[Mon May 23 09:48:14.581916 2016] [:error] [pid 26703] [client 10.0.2.106:37438] ImportError: cannot import name app
[Mon May 23 10:55:21.381378 2016] [:error] [pid 441] [client 10.0.2.106:38223] mod_wsgi (pid=441): Target WSGI script '/var/www/pydrive/controller.wsgi' cannot be loaded as Python module.
[Mon May 23 10:55:21.401834 2016] [:error] [pid 441] [client 10.0.2.106:38223] mod_wsgi (pid=441): Exception occurred processing WSGI script '/var/www/pydrive/controller.wsgi'.
[Mon May 23 10:55:21.401955 2016] [:error] [pid 441] [client 10.0.2.106:38223] Traceback (most recent call last):
[Mon May 23 10:55:21.402004 2016] [:error] [pid 441] [client 10.0.2.106:38223]   File "/var/www/pydrive/controller.wsgi", line 8, in <module>
[Mon May 23 10:55:21.402141 2016] [:error] [pid 441] [client 10.0.2.106:38223]     from pythonapp import app as application
[Mon May 23 10:55:21.402235 2016] [:error] [pid 441] [client 10.0.2.106:38223]   File "/var/www/pydrive/pythonapp/__init__.py", line 31
[Mon May 23 10:55:21.402264 2016] [:error] [pid 441] [client 10.0.2.106:38223]     @app.route('/oauth2callback')
[Mon May 23 10:55:21.402272 2016] [:error] [pid 441] [client 10.0.2.106:38223]                                 ^
[Mon May 23 10:55:21.402279 2016] [:error] [pid 441] [client 10.0.2.106:38223] IndentationError: expected an indented block
[Mon May 23 10:55:42.605298 2016] [:error] [pid 525] [client 10.0.2.106:38224] mod_wsgi (pid=525): Target WSGI script '/var/www/pydrive/controller.wsgi' cannot be loaded as Python module.
[Mon May 23 10:55:42.605360 2016] [:error] [pid 525] [client 10.0.2.106:38224] mod_wsgi (pid=525): Exception occurred processing WSGI script '/var/www/pydrive/controller.wsgi'.
[Mon May 23 10:55:42.605404 2016] [:error] [pid 525] [client 10.0.2.106:38224] Traceback (most recent call last):
[Mon May 23 10:55:42.605444 2016] [:error] [pid 525] [client 10.0.2.106:38224]   File "/var/www/pydrive/controller.wsgi", line 8, in <module>
[Mon May 23 10:55:42.605543 2016] [:error] [pid 525] [client 10.0.2.106:38224]     from pythonapp import app as application
[Mon May 23 10:55:42.605662 2016] [:error] [pid 525] [client 10.0.2.106:38224]   File "/var/www/pydrive/pythonapp/__init__.py", line 39
[Mon May 23 10:55:42.605677 2016] [:error] [pid 525] [client 10.0.2.106:38224]     else 'code' in flask.request.args:
[Mon May 23 10:55:42.605685 2016] [:error] [pid 525] [client 10.0.2.106:38224]               ^
[Mon May 23 10:55:42.605693 2016] [:error] [pid 525] [client 10.0.2.106:38224] SyntaxError: invalid syntax
[Mon May 23 11:24:28.971049 2016] [:error] [pid 1319] [client 10.0.2.106:38524] mod_wsgi (pid=1319): Target WSGI script '/var/www/pydrive/controller.wsgi' cannot be loaded as Python module.
[Mon May 23 11:24:29.009425 2016] [:error] [pid 1319] [client 10.0.2.106:38524] mod_wsgi (pid=1319): Exception occurred processing WSGI script '/var/www/pydrive/controller.wsgi'.
[Mon May 23 11:24:29.009641 2016] [:error] [pid 1319] [client 10.0.2.106:38524] Traceback (most recent call last):
[Mon May 23 11:24:29.009692 2016] [:error] [pid 1319] [client 10.0.2.106:38524]   File "/var/www/pydrive/controller.wsgi", line 8, in <module>
[Mon May 23 11:24:29.009843 2016] [:error] [pid 1319] [client 10.0.2.106:38524]     from pythonapp import app as application
[Mon May 23 11:24:29.009863 2016] [:error] [pid 1319] [client 10.0.2.106:38524]   File "/var/www/pydrive/pythonapp/__init__.py", line 12, in <module>
[Mon May 23 11:24:29.009941 2016] [:error] [pid 1319] [client 10.0.2.106:38524]     sess = flask.session()
[Mon May 23 11:24:29.009960 2016] [:error] [pid 1319] [client 10.0.2.106:38524]   File "/usr/local/lib/python2.7/dist-packages/werkzeug/local.py", line 371, in <lambda>
[Mon May 23 11:24:29.024455 2016] [:error] [pid 1319] [client 10.0.2.106:38524]     __call__ = lambda x, *a, **kw: x._get_current_object()(*a, **kw)
[Mon May 23 11:24:29.024516 2016] [:error] [pid 1319] [client 10.0.2.106:38524]   File "/usr/local/lib/python2.7/dist-packages/werkzeug/local.py", line 302, in _get_current_object
[Mon May 23 11:24:29.024561 2016] [:error] [pid 1319] [client 10.0.2.106:38524]     return self.__local()
[Mon May 23 11:24:29.024576 2016] [:error] [pid 1319] [client 10.0.2.106:38524]   File "/usr/local/lib/python2.7/dist-packages/flask/globals.py", line 20, in _lookup_req_object
[Mon May 23 11:24:29.103751 2016] [:error] [pid 1319] [client 10.0.2.106:38524]     raise RuntimeError('working outside of request context')
[Mon May 23 11:24:29.103843 2016] [:error] [pid 1319] [client 10.0.2.106:38524] RuntimeError: working outside of request context
[Mon May 23 11:28:40.755297 2016] [:error] [pid 1822] [client 10.0.2.106:38535] mod_wsgi (pid=1822): Target WSGI script '/var/www/pydrive/controller.wsgi' cannot be loaded as Python module.
[Mon May 23 11:28:40.755377 2016] [:error] [pid 1822] [client 10.0.2.106:38535] mod_wsgi (pid=1822): Exception occurred processing WSGI script '/var/www/pydrive/controller.wsgi'.
[Mon May 23 11:28:40.755410 2016] [:error] [pid 1822] [client 10.0.2.106:38535] Traceback (most recent call last):
[Mon May 23 11:28:40.755464 2016] [:error] [pid 1822] [client 10.0.2.106:38535]   File "/var/www/pydrive/controller.wsgi", line 8, in <module>
[Mon May 23 11:28:40.755551 2016] [:error] [pid 1822] [client 10.0.2.106:38535]     from pythonapp import app as application
[Mon May 23 11:28:40.755568 2016] [:error] [pid 1822] [client 10.0.2.106:38535]   File "/var/www/pydrive/pythonapp/__init__.py", line 16, in <module>
[Mon May 23 11:28:40.755642 2016] [:error] [pid 1822] [client 10.0.2.106:38535]     Session(app)
[Mon May 23 11:28:40.755660 2016] [:error] [pid 1822] [client 10.0.2.106:38535]   File "/usr/local/lib/python2.7/dist-packages/flask_session/__init__.py", line 54, in __init__
[Mon May 23 11:28:40.755754 2016] [:error] [pid 1822] [client 10.0.2.106:38535]     self.init_app(app)
[Mon May 23 11:28:40.755772 2016] [:error] [pid 1822] [client 10.0.2.106:38535]   File "/usr/local/lib/python2.7/dist-packages/flask_session/__init__.py", line 61, in init_app
[Mon May 23 11:28:40.755797 2016] [:error] [pid 1822] [client 10.0.2.106:38535]     app.session_interface = self._get_interface(app)
[Mon May 23 11:28:40.755811 2016] [:error] [pid 1822] [client 10.0.2.106:38535]   File "/usr/local/lib/python2.7/dist-packages/flask_session/__init__.py", line 84, in _get_interface
[Mon May 23 11:28:40.755830 2016] [:error] [pid 1822] [client 10.0.2.106:38535]     config['SESSION_USE_SIGNER'], config['SESSION_PERMANENT'])
[Mon May 23 11:28:40.755845 2016] [:error] [pid 1822] [client 10.0.2.106:38535]   File "/usr/local/lib/python2.7/dist-packages/flask_session/sessions.py", line 107, in __init__
[Mon May 23 11:28:40.756078 2016] [:error] [pid 1822] [client 10.0.2.106:38535]     from redis import Redis
[Mon May 23 11:28:40.756109 2016] [:error] [pid 1822] [client 10.0.2.106:38535] ImportError: No module named redis
[Mon May 23 11:29:12.544385 2016] [:error] [pid 1823] [client 10.0.2.106:38536] mod_wsgi (pid=1823): Target WSGI script '/var/www/pydrive/controller.wsgi' cannot be loaded as Python module.
[Mon May 23 11:29:12.544481 2016] [:error] [pid 1823] [client 10.0.2.106:38536] mod_wsgi (pid=1823): Exception occurred processing WSGI script '/var/www/pydrive/controller.wsgi'.
[Mon May 23 11:29:12.544523 2016] [:error] [pid 1823] [client 10.0.2.106:38536] Traceback (most recent call last):
[Mon May 23 11:29:12.544685 2016] [:error] [pid 1823] [client 10.0.2.106:38536]   File "/var/www/pydrive/controller.wsgi", line 8, in <module>
[Mon May 23 11:29:12.544858 2016] [:error] [pid 1823] [client 10.0.2.106:38536]     from pythonapp import app as application
[Mon May 23 11:29:12.544883 2016] [:error] [pid 1823] [client 10.0.2.106:38536]   File "/var/www/pydrive/pythonapp/__init__.py", line 5, in <module>
[Mon May 23 11:29:12.545074 2016] [:error] [pid 1823] [client 10.0.2.106:38536]     from redis import Redis
[Mon May 23 11:29:12.545167 2016] [:error] [pid 1823] [client 10.0.2.106:38536] ImportError: No module named redis
[Mon May 23 11:29:14.542032 2016] [:error] [pid 1826] [client 10.0.2.106:38537] mod_wsgi (pid=1826): Target WSGI script '/var/www/pydrive/controller.wsgi' cannot be loaded as Python module.
[Mon May 23 11:29:14.542171 2016] [:error] [pid 1826] [client 10.0.2.106:38537] mod_wsgi (pid=1826): Exception occurred processing WSGI script '/var/www/pydrive/controller.wsgi'.
[Mon May 23 11:29:14.542217 2016] [:error] [pid 1826] [client 10.0.2.106:38537] Traceback (most recent call last):
[Mon May 23 11:29:14.542264 2016] [:error] [pid 1826] [client 10.0.2.106:38537]   File "/var/www/pydrive/controller.wsgi", line 8, in <module>
[Mon May 23 11:29:14.542383 2016] [:error] [pid 1826] [client 10.0.2.106:38537]     from pythonapp import app as application
[Mon May 23 11:29:14.542401 2016] [:error] [pid 1826] [client 10.0.2.106:38537]   File "/var/www/pydrive/pythonapp/__init__.py", line 5, in <module>
[Mon May 23 11:29:14.542487 2016] [:error] [pid 1826] [client 10.0.2.106:38537]     from redis import Redis
[Mon May 23 11:29:14.542532 2016] [:error] [pid 1826] [client 10.0.2.106:38537] ImportError: No module named redis
[Mon May 23 11:30:17.211310 2016] [:error] [pid 1825] [client 10.0.2.106:38562] mod_wsgi (pid=1825): Target WSGI script '/var/www/pydrive/controller.wsgi' cannot be loaded as Python module.
[Mon May 23 11:30:17.211406 2016] [:error] [pid 1825] [client 10.0.2.106:38562] mod_wsgi (pid=1825): Exception occurred processing WSGI script '/var/www/pydrive/controller.wsgi'.
[Mon May 23 11:30:17.211443 2016] [:error] [pid 1825] [client 10.0.2.106:38562] Traceback (most recent call last):
[Mon May 23 11:30:17.211595 2016] [:error] [pid 1825] [client 10.0.2.106:38562]   File "/var/www/pydrive/controller.wsgi", line 8, in <module>
[Mon May 23 11:30:17.211805 2016] [:error] [pid 1825] [client 10.0.2.106:38562]     from pythonapp import app as application
[Mon May 23 11:30:17.211838 2016] [:error] [pid 1825] [client 10.0.2.106:38562]   File "/var/www/pydrive/pythonapp/__init__.py", line 18, in <module>
[Mon May 23 11:30:17.212033 2016] [:error] [pid 1825] [client 10.0.2.106:38562]     sess = flask.session()
[Mon May 23 11:30:17.212062 2016] [:error] [pid 1825] [client 10.0.2.106:38562]   File "/usr/local/lib/python2.7/dist-packages/werkzeug/local.py", line 371, in <lambda>
[Mon May 23 11:30:17.227385 2016] [:error] [pid 1825] [client 10.0.2.106:38562]     __call__ = lambda x, *a, **kw: x._get_current_object()(*a, **kw)
[Mon May 23 11:30:17.227444 2016] [:error] [pid 1825] [client 10.0.2.106:38562]   File "/usr/local/lib/python2.7/dist-packages/werkzeug/local.py", line 302, in _get_current_object
[Mon May 23 11:30:17.227558 2016] [:error] [pid 1825] [client 10.0.2.106:38562]     return self.__local()
[Mon May 23 11:30:17.227578 2016] [:error] [pid 1825] [client 10.0.2.106:38562]   File "/usr/local/lib/python2.7/dist-packages/flask/globals.py", line 20, in _lookup_req_object
[Mon May 23 11:30:17.242234 2016] [:error] [pid 1825] [client 10.0.2.106:38562]     raise RuntimeError('working outside of request context')
[Mon May 23 11:30:17.242360 2016] [:error] [pid 1825] [client 10.0.2.106:38562] RuntimeError: working outside of request context
[Mon May 23 11:30:59.156699 2016] [:error] [pid 1824] [client 10.0.2.106:38565] mod_wsgi (pid=1824): Target WSGI script '/var/www/pydrive/controller.wsgi' cannot be loaded as Python module.
[Mon May 23 11:30:59.156942 2016] [:error] [pid 1824] [client 10.0.2.106:38565] mod_wsgi (pid=1824): Exception occurred processing WSGI script '/var/www/pydrive/controller.wsgi'.
[Mon May 23 11:30:59.157053 2016] [:error] [pid 1824] [client 10.0.2.106:38565] Traceback (most recent call last):
[Mon May 23 11:30:59.157170 2016] [:error] [pid 1824] [client 10.0.2.106:38565]   File "/var/www/pydrive/controller.wsgi", line 8, in <module>
[Mon May 23 11:30:59.157510 2016] [:error] [pid 1824] [client 10.0.2.106:38565]     from pythonapp import app as application
[Mon May 23 11:30:59.157724 2016] [:error] [pid 1824] [client 10.0.2.106:38565]   File "/var/www/pydrive/pythonapp/__init__.py", line 16, in <module>
[Mon May 23 11:30:59.158003 2016] [:error] [pid 1824] [client 10.0.2.106:38565]     sess = flask.session()
[Mon May 23 11:30:59.158212 2016] [:error] [pid 1824] [client 10.0.2.106:38565]   File "/usr/local/lib/python2.7/dist-packages/werkzeug/local.py", line 371, in <lambda>
[Mon May 23 11:30:59.158557 2016] [:error] [pid 1824] [client 10.0.2.106:38565]     __call__ = lambda x, *a, **kw: x._get_current_object()(*a, **kw)
[Mon May 23 11:30:59.158687 2016] [:error] [pid 1824] [client 10.0.2.106:38565]   File "/usr/local/lib/python2.7/dist-packages/werkzeug/local.py", line 302, in _get_current_object
[Mon May 23 11:30:59.158798 2016] [:error] [pid 1824] [client 10.0.2.106:38565]     return self.__local()
[Mon May 23 11:30:59.158885 2016] [:error] [pid 1824] [client 10.0.2.106:38565]   File "/usr/local/lib/python2.7/dist-packages/flask/globals.py", line 20, in _lookup_req_object
[Mon May 23 11:30:59.159059 2016] [:error] [pid 1824] [client 10.0.2.106:38565]     raise RuntimeError('working outside of request context')
[Mon May 23 11:30:59.159195 2016] [:error] [pid 1824] [client 10.0.2.106:38565] RuntimeError: working outside of request context
[Mon May 23 11:31:08.351607 2016] [:error] [pid 1839] [client 10.0.2.106:38566] mod_wsgi (pid=1839): Target WSGI script '/var/www/pydrive/controller.wsgi' cannot be loaded as Python module.
[Mon May 23 11:31:08.351731 2016] [:error] [pid 1839] [client 10.0.2.106:38566] mod_wsgi (pid=1839): Exception occurred processing WSGI script '/var/www/pydrive/controller.wsgi'.
[Mon May 23 11:31:08.351789 2016] [:error] [pid 1839] [client 10.0.2.106:38566] Traceback (most recent call last):
[Mon May 23 11:31:08.351834 2016] [:error] [pid 1839] [client 10.0.2.106:38566]   File "/var/www/pydrive/controller.wsgi", line 8, in <module>
[Mon May 23 11:31:08.351988 2016] [:error] [pid 1839] [client 10.0.2.106:38566]     from pythonapp import app as application
[Mon May 23 11:31:08.352011 2016] [:error] [pid 1839] [client 10.0.2.106:38566]   File "/var/www/pydrive/pythonapp/__init__.py", line 14, in <module>
[Mon May 23 11:31:08.352085 2016] [:error] [pid 1839] [client 10.0.2.106:38566]     sess = flask.session()
[Mon May 23 11:31:08.352101 2016] [:error] [pid 1839] [client 10.0.2.106:38566]   File "/usr/local/lib/python2.7/dist-packages/werkzeug/local.py", line 371, in <lambda>
[Mon May 23 11:31:08.352308 2016] [:error] [pid 1839] [client 10.0.2.106:38566]     __call__ = lambda x, *a, **kw: x._get_current_object()(*a, **kw)
[Mon May 23 11:31:08.352332 2016] [:error] [pid 1839] [client 10.0.2.106:38566]   File "/usr/local/lib/python2.7/dist-packages/werkzeug/local.py", line 302, in _get_current_object
[Mon May 23 11:31:08.352362 2016] [:error] [pid 1839] [client 10.0.2.106:38566]     return self.__local()
[Mon May 23 11:31:08.352377 2016] [:error] [pid 1839] [client 10.0.2.106:38566]   File "/usr/local/lib/python2.7/dist-packages/flask/globals.py", line 20, in _lookup_req_object
[Mon May 23 11:31:08.352440 2016] [:error] [pid 1839] [client 10.0.2.106:38566]     raise RuntimeError('working outside of request context')
[Mon May 23 11:31:08.352475 2016] [:error] [pid 1839] [client 10.0.2.106:38566] RuntimeError: working outside of request context
[Mon May 23 11:31:19.101554 2016] [:error] [pid 2104] [client 10.0.2.106:38567] mod_wsgi (pid=2104): Target WSGI script '/var/www/pydrive/controller.wsgi' cannot be loaded as Python module.
[Mon May 23 11:31:19.101718 2016] [:error] [pid 2104] [client 10.0.2.106:38567] mod_wsgi (pid=2104): Exception occurred processing WSGI script '/var/www/pydrive/controller.wsgi'.
[Mon May 23 11:31:19.101772 2016] [:error] [pid 2104] [client 10.0.2.106:38567] Traceback (most recent call last):
[Mon May 23 11:31:19.101817 2016] [:error] [pid 2104] [client 10.0.2.106:38567]   File "/var/www/pydrive/controller.wsgi", line 8, in <module>
[Mon May 23 11:31:19.101923 2016] [:error] [pid 2104] [client 10.0.2.106:38567]     from pythonapp import app as application
[Mon May 23 11:31:19.101943 2016] [:error] [pid 2104] [client 10.0.2.106:38567]   File "/var/www/pydrive/pythonapp/__init__.py", line 14, in <module>
[Mon May 23 11:31:19.102018 2016] [:error] [pid 2104] [client 10.0.2.106:38567]     sess = flask.session()
[Mon May 23 11:31:19.102037 2016] [:error] [pid 2104] [client 10.0.2.106:38567]   File "/usr/local/lib/python2.7/dist-packages/werkzeug/local.py", line 371, in <lambda>
[Mon May 23 11:31:19.102228 2016] [:error] [pid 2104] [client 10.0.2.106:38567]     __call__ = lambda x, *a, **kw: x._get_current_object()(*a, **kw)
[Mon May 23 11:31:19.102248 2016] [:error] [pid 2104] [client 10.0.2.106:38567]   File "/usr/local/lib/python2.7/dist-packages/werkzeug/local.py", line 302, in _get_current_object
[Mon May 23 11:31:19.102275 2016] [:error] [pid 2104] [client 10.0.2.106:38567]     return self.__local()
[Mon May 23 11:31:19.102290 2016] [:error] [pid 2104] [client 10.0.2.106:38567]   File "/usr/local/lib/python2.7/dist-packages/flask/globals.py", line 20, in _lookup_req_object
[Mon May 23 11:31:19.102354 2016] [:error] [pid 2104] [client 10.0.2.106:38567]     raise RuntimeError('working outside of request context')
[Mon May 23 11:31:19.102384 2016] [:error] [pid 2104] [client 10.0.2.106:38567] RuntimeError: working outside of request context
[Mon May 23 11:32:01.189353 2016] [:error] [pid 2218] [client 10.0.2.106:38569] mod_wsgi (pid=2218): Target WSGI script '/var/www/pydrive/controller.wsgi' cannot be loaded as Python module.
[Mon May 23 11:32:01.189481 2016] [:error] [pid 2218] [client 10.0.2.106:38569] mod_wsgi (pid=2218): Exception occurred processing WSGI script '/var/www/pydrive/controller.wsgi'.
[Mon May 23 11:32:01.189525 2016] [:error] [pid 2218] [client 10.0.2.106:38569] Traceback (most recent call last):
[Mon May 23 11:32:01.189567 2016] [:error] [pid 2218] [client 10.0.2.106:38569]   File "/var/www/pydrive/controller.wsgi", line 8, in <module>
[Mon May 23 11:32:01.189711 2016] [:error] [pid 2218] [client 10.0.2.106:38569]     from pythonapp import app as application
[Mon May 23 11:32:01.189733 2016] [:error] [pid 2218] [client 10.0.2.106:38569]   File "/var/www/pydrive/pythonapp/__init__.py", line 13, in <module>
[Mon May 23 11:32:01.189806 2016] [:error] [pid 2218] [client 10.0.2.106:38569]     sess = flask.session()
[Mon May 23 11:32:01.189826 2016] [:error] [pid 2218] [client 10.0.2.106:38569]   File "/usr/local/lib/python2.7/dist-packages/werkzeug/local.py", line 371, in <lambda>
[Mon May 23 11:32:01.190018 2016] [:error] [pid 2218] [client 10.0.2.106:38569]     __call__ = lambda x, *a, **kw: x._get_current_object()(*a, **kw)
[Mon May 23 11:32:01.190039 2016] [:error] [pid 2218] [client 10.0.2.106:38569]   File "/usr/local/lib/python2.7/dist-packages/werkzeug/local.py", line 302, in _get_current_object
[Mon May 23 11:32:01.190067 2016] [:error] [pid 2218] [client 10.0.2.106:38569]     return self.__local()
[Mon May 23 11:32:01.190081 2016] [:error] [pid 2218] [client 10.0.2.106:38569]   File "/usr/local/lib/python2.7/dist-packages/flask/globals.py", line 20, in _lookup_req_object
[Mon May 23 11:32:01.190147 2016] [:error] [pid 2218] [client 10.0.2.106:38569]     raise RuntimeError('working outside of request context')
[Mon May 23 11:32:01.190179 2016] [:error] [pid 2218] [client 10.0.2.106:38569] RuntimeError: working outside of request context
[Mon May 23 11:55:47.503732 2016] [:error] [pid 3018] [client 10.0.2.106:38815] mod_wsgi (pid=3018, process='', application='drivepython.example.com|'): Failed to parse WSGI script file '/var/www/pydrive/controller.wsgi'.
[Mon May 23 11:55:47.604735 2016] [:error] [pid 3018] [client 10.0.2.106:38815] mod_wsgi (pid=3018): Exception occurred processing WSGI script '/var/www/pydrive/controller.wsgi'.
[Mon May 23 11:55:47.604897 2016] [:error] [pid 3018] [client 10.0.2.106:38815]   File "/var/www/pydrive/controller.wsgi", line 9
[Mon May 23 11:55:47.604919 2016] [:error] [pid 3018] [client 10.0.2.106:38815]     application.secret_key = "A0Zr98j/3yX R~XHH!jmN]LWX/,?RT"
[Mon May 23 11:55:47.604928 2016] [:error] [pid 3018] [client 10.0.2.106:38815]     ^
[Mon May 23 11:55:47.604937 2016] [:error] [pid 3018] [client 10.0.2.106:38815] IndentationError: unexpected indent
[Mon May 23 12:13:57.374710 2016] [:error] [pid 3723] [client 10.0.2.106:39005] mod_wsgi (pid=3723): Target WSGI script '/var/www/pydrive/controller.wsgi' cannot be loaded as Python module.
[Mon May 23 12:13:57.400885 2016] [:error] [pid 3723] [client 10.0.2.106:39005] mod_wsgi (pid=3723): Exception occurred processing WSGI script '/var/www/pydrive/controller.wsgi'.
[Mon May 23 12:13:57.400963 2016] [:error] [pid 3723] [client 10.0.2.106:39005] Traceback (most recent call last):
[Mon May 23 12:13:57.401004 2016] [:error] [pid 3723] [client 10.0.2.106:39005]   File "/var/www/pydrive/controller.wsgi", line 8, in <module>
[Mon May 23 12:13:57.401106 2016] [:error] [pid 3723] [client 10.0.2.106:39005]     from pythonapp import app as application
[Mon May 23 12:13:57.401124 2016] [:error] [pid 3723] [client 10.0.2.106:39005]   File "/var/www/pydrive/pythonapp/__init__.py", line 14, in <module>
[Mon May 23 12:13:57.401199 2016] [:error] [pid 3723] [client 10.0.2.106:39005]     Session(app)
[Mon May 23 12:13:57.401215 2016] [:error] [pid 3723] [client 10.0.2.106:39005]   File "/usr/local/lib/python2.7/dist-packages/flask/sessions.py", line 115, in __init__
[Mon May 23 12:13:57.439480 2016] [:error] [pid 3723] [client 10.0.2.106:39005]     CallbackDict.__init__(self, initial, on_update)
[Mon May 23 12:13:57.439605 2016] [:error] [pid 3723] [client 10.0.2.106:39005]   File "/usr/local/lib/python2.7/dist-packages/werkzeug/datastructures.py", line 1948, in __init__
[Mon May 23 12:13:57.509910 2016] [:error] [pid 3723] [client 10.0.2.106:39005]     dict.__init__(self, initial or ())
[Mon May 23 12:13:57.509986 2016] [:error] [pid 3723] [client 10.0.2.106:39005] TypeError: 'Flask' object is not iterable
[Mon May 23 12:13:57.560387 2016] [:error] [pid 3721] [client 10.0.2.106:39006] mod_wsgi (pid=3721): Target WSGI script '/var/www/pydrive/controller.wsgi' cannot be loaded as Python module.
[Mon May 23 12:13:57.560486 2016] [:error] [pid 3721] [client 10.0.2.106:39006] mod_wsgi (pid=3721): Exception occurred processing WSGI script '/var/www/pydrive/controller.wsgi'.
[Mon May 23 12:13:57.560527 2016] [:error] [pid 3721] [client 10.0.2.106:39006] Traceback (most recent call last):
[Mon May 23 12:13:57.560559 2016] [:error] [pid 3721] [client 10.0.2.106:39006]   File "/var/www/pydrive/controller.wsgi", line 8, in <module>
[Mon May 23 12:13:57.560665 2016] [:error] [pid 3721] [client 10.0.2.106:39006]     from pythonapp import app as application
[Mon May 23 12:13:57.560685 2016] [:error] [pid 3721] [client 10.0.2.106:39006]   File "/var/www/pydrive/pythonapp/__init__.py", line 14, in <module>
[Mon May 23 12:13:57.560757 2016] [:error] [pid 3721] [client 10.0.2.106:39006]     Session(app)
[Mon May 23 12:13:57.560775 2016] [:error] [pid 3721] [client 10.0.2.106:39006]   File "/usr/local/lib/python2.7/dist-packages/flask/sessions.py", line 115, in __init__
[Mon May 23 12:13:57.560953 2016] [:error] [pid 3721] [client 10.0.2.106:39006]     CallbackDict.__init__(self, initial, on_update)
[Mon May 23 12:13:57.560973 2016] [:error] [pid 3721] [client 10.0.2.106:39006]   File "/usr/local/lib/python2.7/dist-packages/werkzeug/datastructures.py", line 1948, in __init__
[Mon May 23 12:13:57.561906 2016] [:error] [pid 3721] [client 10.0.2.106:39006]     dict.__init__(self, initial or ())
[Mon May 23 12:13:57.561975 2016] [:error] [pid 3721] [client 10.0.2.106:39006] TypeError: 'Flask' object is not iterable
[Mon May 23 12:21:02.889730 2016] [:error] [pid 4240] [client 10.0.2.106:39084] mod_wsgi (pid=4240): Target WSGI script '/var/www/pydrive/controller.wsgi' cannot be loaded as Python module.
[Mon May 23 12:21:02.889846 2016] [:error] [pid 4240] [client 10.0.2.106:39084] mod_wsgi (pid=4240): Exception occurred processing WSGI script '/var/www/pydrive/controller.wsgi'.
[Mon May 23 12:21:02.890086 2016] [:error] [pid 4240] [client 10.0.2.106:39084] Traceback (most recent call last):
[Mon May 23 12:21:02.890208 2016] [:error] [pid 4240] [client 10.0.2.106:39084]   File "/var/www/pydrive/controller.wsgi", line 8, in <module>
[Mon May 23 12:21:02.890705 2016] [:error] [pid 4240] [client 10.0.2.106:39084]     from pythonapp import app as application
[Mon May 23 12:21:02.890892 2016] [:error] [pid 4240] [client 10.0.2.106:39084]   File "/var/www/pydrive/pythonapp/__init__.py", line 21
[Mon May 23 12:21:02.890909 2016] [:error] [pid 4240] [client 10.0.2.106:39084]     return "hoal yes in sess"
[Mon May 23 12:21:02.890918 2016] [:error] [pid 4240] [client 10.0.2.106:39084]     ^
[Mon May 23 12:21:02.890977 2016] [:error] [pid 4240] [client 10.0.2.106:39084] IndentationError: unexpected indent
[Mon May 23 16:13:11.287401 2016] [:error] [pid 10697] [client 10.0.2.106:41271] mod_wsgi (pid=10697): Target WSGI script '/var/www/pydrive/controller.wsgi' cannot be loaded as Python module.
[Mon May 23 16:13:11.287454 2016] [:error] [pid 10697] [client 10.0.2.106:41271] mod_wsgi (pid=10697): Exception occurred processing WSGI script '/var/www/pydrive/controller.wsgi'.
[Mon May 23 16:13:11.287497 2016] [:error] [pid 10697] [client 10.0.2.106:41271] Traceback (most recent call last):
[Mon May 23 16:13:11.287533 2016] [:error] [pid 10697] [client 10.0.2.106:41271]   File "/var/www/pydrive/controller.wsgi", line 8, in <module>
[Mon May 23 16:13:11.287638 2016] [:error] [pid 10697] [client 10.0.2.106:41271]     from pythonapp import app as application
[Mon May 23 16:13:11.287699 2016] [:error] [pid 10697] [client 10.0.2.106:41271]   File "/var/www/pydrive/pythonapp/__init__.py", line 60
[Mon May 23 16:13:11.287709 2016] [:error] [pid 10697] [client 10.0.2.106:41271]     drive_service = discovery.build('drive', 'v2', http_auth)
[Mon May 23 16:13:11.287717 2016] [:error] [pid 10697] [client 10.0.2.106:41271]     ^
[Mon May 23 16:13:11.287734 2016] [:error] [pid 10697] [client 10.0.2.106:41271] IndentationError: unexpected indent
[Mon May 23 16:13:26.616156 2016] [:error] [pid 10760] [client 10.0.2.106:41273] mod_wsgi (pid=10760): Target WSGI script '/var/www/pydrive/controller.wsgi' cannot be loaded as Python module.
[Mon May 23 16:13:26.616217 2016] [:error] [pid 10760] [client 10.0.2.106:41273] mod_wsgi (pid=10760): Exception occurred processing WSGI script '/var/www/pydrive/controller.wsgi'.
[Mon May 23 16:13:26.616265 2016] [:error] [pid 10760] [client 10.0.2.106:41273] Traceback (most recent call last):
[Mon May 23 16:13:26.616307 2016] [:error] [pid 10760] [client 10.0.2.106:41273]   File "/var/www/pydrive/controller.wsgi", line 8, in <module>
[Mon May 23 16:13:26.616404 2016] [:error] [pid 10760] [client 10.0.2.106:41273]     from pythonapp import app as application
[Mon May 23 16:13:26.616478 2016] [:error] [pid 10760] [client 10.0.2.106:41273]   File "/var/www/pydrive/pythonapp/__init__.py", line 63
[Mon May 23 16:13:26.616491 2016] [:error] [pid 10760] [client 10.0.2.106:41273]     for i in items {
[Mon May 23 16:13:26.616499 2016] [:error] [pid 10760] [client 10.0.2.106:41273]                    ^
[Mon May 23 16:13:26.616509 2016] [:error] [pid 10760] [client 10.0.2.106:41273] SyntaxError: invalid syntax
[Mon May 23 16:13:27.262794 2016] [:error] [pid 10763] [client 10.0.2.106:41274] mod_wsgi (pid=10763): Target WSGI script '/var/www/pydrive/controller.wsgi' cannot be loaded as Python module.
[Mon May 23 16:13:27.262867 2016] [:error] [pid 10763] [client 10.0.2.106:41274] mod_wsgi (pid=10763): Exception occurred processing WSGI script '/var/www/pydrive/controller.wsgi'.
[Mon May 23 16:13:27.262911 2016] [:error] [pid 10763] [client 10.0.2.106:41274] Traceback (most recent call last):
[Mon May 23 16:13:27.263101 2016] [:error] [pid 10763] [client 10.0.2.106:41274]   File "/var/www/pydrive/controller.wsgi", line 8, in <module>
[Mon May 23 16:13:27.263237 2016] [:error] [pid 10763] [client 10.0.2.106:41274]     from pythonapp import app as application
[Mon May 23 16:13:27.263354 2016] [:error] [pid 10763] [client 10.0.2.106:41274]   File "/var/www/pydrive/pythonapp/__init__.py", line 63
[Mon May 23 16:13:27.263368 2016] [:error] [pid 10763] [client 10.0.2.106:41274]     for i in items {
[Mon May 23 16:13:27.263376 2016] [:error] [pid 10763] [client 10.0.2.106:41274]                    ^
[Mon May 23 16:13:27.263427 2016] [:error] [pid 10763] [client 10.0.2.106:41274] SyntaxError: invalid syntax
[Mon May 23 16:13:27.764405 2016] [:error] [pid 10759] [client 10.0.2.106:41275] mod_wsgi (pid=10759): Target WSGI script '/var/www/pydrive/controller.wsgi' cannot be loaded as Python module.
[Mon May 23 16:13:27.764473 2016] [:error] [pid 10759] [client 10.0.2.106:41275] mod_wsgi (pid=10759): Exception occurred processing WSGI script '/var/www/pydrive/controller.wsgi'.
[Mon May 23 16:13:27.764519 2016] [:error] [pid 10759] [client 10.0.2.106:41275] Traceback (most recent call last):
[Mon May 23 16:13:27.764561 2016] [:error] [pid 10759] [client 10.0.2.106:41275]   File "/var/www/pydrive/controller.wsgi", line 8, in <module>
[Mon May 23 16:13:27.764658 2016] [:error] [pid 10759] [client 10.0.2.106:41275]     from pythonapp import app as application
[Mon May 23 16:13:27.764734 2016] [:error] [pid 10759] [client 10.0.2.106:41275]   File "/var/www/pydrive/pythonapp/__init__.py", line 63
[Mon May 23 16:13:27.764748 2016] [:error] [pid 10759] [client 10.0.2.106:41275]     for i in items {
[Mon May 23 16:13:27.764773 2016] [:error] [pid 10759] [client 10.0.2.106:41275]                    ^
[Mon May 23 16:13:27.764781 2016] [:error] [pid 10759] [client 10.0.2.106:41275] SyntaxError: invalid syntax
[Mon May 23 16:13:29.057575 2016] [:error] [pid 10761] [client 10.0.2.106:41276] mod_wsgi (pid=10761): Target WSGI script '/var/www/pydrive/controller.wsgi' cannot be loaded as Python module.
[Mon May 23 16:13:29.057716 2016] [:error] [pid 10761] [client 10.0.2.106:41276] mod_wsgi (pid=10761): Exception occurred processing WSGI script '/var/www/pydrive/controller.wsgi'.
[Mon May 23 16:13:29.057795 2016] [:error] [pid 10761] [client 10.0.2.106:41276] Traceback (most recent call last):
[Mon May 23 16:13:29.057857 2016] [:error] [pid 10761] [client 10.0.2.106:41276]   File "/var/www/pydrive/controller.wsgi", line 8, in <module>
[Mon May 23 16:13:29.057990 2016] [:error] [pid 10761] [client 10.0.2.106:41276]     from pythonapp import app as application
[Mon May 23 16:13:29.058080 2016] [:error] [pid 10761] [client 10.0.2.106:41276]   File "/var/www/pydrive/pythonapp/__init__.py", line 63
[Mon May 23 16:13:29.058093 2016] [:error] [pid 10761] [client 10.0.2.106:41276]     for i in items {
[Mon May 23 16:13:29.058101 2016] [:error] [pid 10761] [client 10.0.2.106:41276]                    ^
[Mon May 23 16:13:29.058111 2016] [:error] [pid 10761] [client 10.0.2.106:41276] SyntaxError: invalid syntax
[Mon May 23 16:13:29.544872 2016] [:error] [pid 10762] [client 10.0.2.106:41277] mod_wsgi (pid=10762): Target WSGI script '/var/www/pydrive/controller.wsgi' cannot be loaded as Python module.
[Mon May 23 16:13:29.545092 2016] [:error] [pid 10762] [client 10.0.2.106:41277] mod_wsgi (pid=10762): Exception occurred processing WSGI script '/var/www/pydrive/controller.wsgi'.
[Mon May 23 16:13:29.545192 2016] [:error] [pid 10762] [client 10.0.2.106:41277] Traceback (most recent call last):
[Mon May 23 16:13:29.545284 2016] [:error] [pid 10762] [client 10.0.2.106:41277]   File "/var/www/pydrive/controller.wsgi", line 8, in <module>
[Mon May 23 16:13:29.545431 2016] [:error] [pid 10762] [client 10.0.2.106:41277]     from pythonapp import app as application
[Mon May 23 16:13:29.545555 2016] [:error] [pid 10762] [client 10.0.2.106:41277]   File "/var/www/pydrive/pythonapp/__init__.py", line 63
[Mon May 23 16:13:29.545694 2016] [:error] [pid 10762] [client 10.0.2.106:41277]     for i in items {
[Mon May 23 16:13:29.545758 2016] [:error] [pid 10762] [client 10.0.2.106:41277]                    ^
[Mon May 23 16:13:29.545816 2016] [:error] [pid 10762] [client 10.0.2.106:41277] SyntaxError: invalid syntax
[Mon May 23 16:13:30.171308 2016] [:error] [pid 10760] [client 10.0.2.106:41278] mod_wsgi (pid=10760): Target WSGI script '/var/www/pydrive/controller.wsgi' cannot be loaded as Python module.
[Mon May 23 16:13:30.171381 2016] [:error] [pid 10760] [client 10.0.2.106:41278] mod_wsgi (pid=10760): Exception occurred processing WSGI script '/var/www/pydrive/controller.wsgi'.
[Mon May 23 16:13:30.171425 2016] [:error] [pid 10760] [client 10.0.2.106:41278] Traceback (most recent call last):
[Mon May 23 16:13:30.171465 2016] [:error] [pid 10760] [client 10.0.2.106:41278]   File "/var/www/pydrive/controller.wsgi", line 8, in <module>
[Mon May 23 16:13:30.171520 2016] [:error] [pid 10760] [client 10.0.2.106:41278]     from pythonapp import app as application
[Mon May 23 16:13:30.171556 2016] [:error] [pid 10760] [client 10.0.2.106:41278] ImportError: cannot import name app
[Mon May 23 18:29:11.564818 2016] [:error] [pid 19134] [client 10.0.2.106:43119] mod_wsgi (pid=19134): Target WSGI script '/var/www/pydrive/controller.wsgi' cannot be loaded as Python module.
[Mon May 23 18:29:11.592114 2016] [:error] [pid 19134] [client 10.0.2.106:43119] mod_wsgi (pid=19134): Exception occurred processing WSGI script '/var/www/pydrive/controller.wsgi'.
[Mon May 23 18:29:11.592273 2016] [:error] [pid 19134] [client 10.0.2.106:43119] Traceback (most recent call last):
[Mon May 23 18:29:11.592330 2016] [:error] [pid 19134] [client 10.0.2.106:43119]   File "/var/www/pydrive/controller.wsgi", line 8, in <module>
[Mon May 23 18:29:11.592533 2016] [:error] [pid 19134] [client 10.0.2.106:43119]     from pythonapp import app as application
[Mon May 23 18:29:11.592612 2016] [:error] [pid 19134] [client 10.0.2.106:43119]   File "/var/www/pydrive/pythonapp/__init__.py", line 70
[Mon May 23 18:29:11.592621 2016] [:error] [pid 19134] [client 10.0.2.106:43119]     return "dsfjsdoifj"
[Mon May 23 18:29:11.592629 2016] [:error] [pid 19134] [client 10.0.2.106:43119]     ^
[Mon May 23 18:29:11.592636 2016] [:error] [pid 19134] [client 10.0.2.106:43119] IndentationError: unexpected indent
